{"trial_id": "04", "hyperparameters": {"space": [{"class_name": "Int", "config": {"name": "units", "default": null, "conditions": [], "min_value": 32, "max_value": 256, "step": 32, "sampling": "linear"}}, {"class_name": "Float", "config": {"name": "dropout", "default": 0.1, "conditions": [], "min_value": 0.1, "max_value": 0.5, "step": 0.1, "sampling": "linear"}}, {"class_name": "Int", "config": {"name": "units_2", "default": null, "conditions": [], "min_value": 32, "max_value": 128, "step": 32, "sampling": "linear"}}, {"class_name": "Float", "config": {"name": "dropout_2", "default": 0.1, "conditions": [], "min_value": 0.1, "max_value": 0.5, "step": 0.1, "sampling": "linear"}}], "values": {"units": 224, "dropout": 0.5, "units_2": 64, "dropout_2": 0.30000000000000004}}, "metrics": {"metrics": {}}, "score": null, "best_step": 0, "status": "FAILED", "message": "Traceback (most recent call last):\n  File \"c:\\Users\\richa\\AppData\\Local\\Programs\\Python\\Python311\\Lib\\site-packages\\keras_tuner\\src\\engine\\base_tuner.py\", line 274, in _try_run_and_update_trial\n    self._run_and_update_trial(trial, *fit_args, **fit_kwargs)\n  File \"c:\\Users\\richa\\AppData\\Local\\Programs\\Python\\Python311\\Lib\\site-packages\\keras_tuner\\src\\engine\\base_tuner.py\", line 239, in _run_and_update_trial\n    results = self.run_trial(trial, *fit_args, **fit_kwargs)\n              ^^^^^^^^^^^^^^^^^^^^^^^^^^^^^^^^^^^^^^^^^^^^^^\n  File \"c:\\Users\\richa\\AppData\\Local\\Programs\\Python\\Python311\\Lib\\site-packages\\keras_tuner\\src\\engine\\tuner.py\", line 314, in run_trial\n    obj_value = self._build_and_fit_model(trial, *args, **copied_kwargs)\n                ^^^^^^^^^^^^^^^^^^^^^^^^^^^^^^^^^^^^^^^^^^^^^^^^^^^^^^^^\n  File \"c:\\Users\\richa\\AppData\\Local\\Programs\\Python\\Python311\\Lib\\site-packages\\keras_tuner\\src\\engine\\tuner.py\", line 233, in _build_and_fit_model\n    results = self.hypermodel.fit(hp, model, *args, **kwargs)\n              ^^^^^^^^^^^^^^^^^^^^^^^^^^^^^^^^^^^^^^^^^^^^^^^\n  File \"c:\\Users\\richa\\AppData\\Local\\Programs\\Python\\Python311\\Lib\\site-packages\\keras_tuner\\src\\engine\\hypermodel.py\", line 149, in fit\n    return model.fit(*args, **kwargs)\n           ^^^^^^^^^^^^^^^^^^^^^^^^^^\n  File \"c:\\Users\\richa\\AppData\\Local\\Programs\\Python\\Python311\\Lib\\site-packages\\keras\\src\\utils\\traceback_utils.py\", line 70, in error_handler\n    raise e.with_traceback(filtered_tb) from None\n  File \"c:\\Users\\richa\\AppData\\Local\\Programs\\Python\\Python311\\Lib\\site-packages\\keras_tuner\\src\\engine\\tuner_utils.py\", line 76, in on_epoch_end\n    self._save_model()\n  File \"c:\\Users\\richa\\AppData\\Local\\Programs\\Python\\Python311\\Lib\\site-packages\\keras_tuner\\src\\engine\\tuner_utils.py\", line 86, in _save_model\n    self.model.save_weights(write_filepath)\ntensorflow.python.framework.errors_impl.FailedPreconditionError: {{function_node __wrapped__MergeV2Checkpoints_device_/job:localhost/replica:0/task:0/device:CPU:0}} Failed to rename: hyperparameter_tuning\\lstm_stock_prediction\\trial_04\\checkpoint_temp/part-00000-of-00001.data-00000-of-00001 to: hyperparameter_tuning\\lstm_stock_prediction\\trial_04\\checkpoint.data-00000-of-00001 : The process cannot access the file because it is being used by another process.\r\n; Broken pipe [Op:MergeV2Checkpoints]\n"}